Workbook

Sheet README
B2: FLOODGUARD STO. NIÑO: PRE-HOLDOUT DEFENSE PROOF WORKBOOK
B3: Rule #33 Formula-Native Verification & Statistical Inference Audit | Generated: 2026-08-17 23:54:38
B5: 1. EXECUTIVE MANDATE & GOVERNANCE COMPLIANCE
B6: • This workbook provides 100% live formula proof for all derived values in the Pre-Holdout Modeling phase (2016-01-01 to 2023-12-31).
B7: • Dates are stored as genuine Excel date values (yyyy-mm-dd), OLS coefficients are computed via INDEX(LINEST(...)), and all validation metrics are live formulas.
B8: • Clicking any calculated cell reveals its live formula in Excel's formula bar.
B10: 2. TRUE OPERATIONAL HOLDOUT SEAL
B11: • The modeling input is constructed strictly from PREHOLDOUT_DAILY_INPUT_2016_2023.csv (exactly 2,922 calendar days).
B12: • Zero 2024–2025 rows enter memory, scripts, or workbook sheets.
B13: • Training Split: 2016-01-01 to 2022-05-26 (N_cal = 2,338 days).
B14: • Validation Split: 2022-05-27 to 2023-12-31 (N_cal = 584 days).
B15: • Holdout Split: 2024-01-01 to 2025-12-31 (N_cal = 731 days) [SEALED / UNTOUCHED].
... B30: • Sheet 'Model_Selection_Audit': Condorcet tournament rankings, OLS vs HC3 statistics, and audit notes.

Sheet Formula_Audit
B2: RULE #33 FORMULA AUDIT & REPRODUCIBILITY CATALOG
B3: Catalog of all active formula patterns across proof sheets (displayed as text strings)
B5: Sheet Name | C5: Calculated Range | D5: Primary Formula Pattern (Text) | E5: Source Range / Inputs | F5: Mathematical Description
B6: Train_Cand_15 | C6: K2:K6 | D6: INDEX(LINEST(B2:B1771, C2:F1771, TRUE, FALSE), 1, {pos}) | E6: Cols B (Y), C..F (X) | F6: OLS regression coefficients beta_0..beta_4 via Excel LINEST
B7: Train_Cand_15 | C7: G2:G1771 | D7: $K$2 + $K$3*C2 + $K$4*D2 + $K$5*E2 + $K$6*F2 | E7: Cols C..F, Betas K2:K6 | F7: Fitted water level OLS prediction on Training set
B8: Train_Cand_15 | C8: H2:H1771 | D8: B2 - G2 | E8: Col B (Actual), Col G (Pred) | F8: Regression residual (e = Y - Y_hat)
B9: Train_Cand_15 | C9: I2:I1771 | D9: ABS(H2) | E9: Col H (Residual) | F9: Absolute error magnitude |e|
B10: Train_Cand_15 | C10: J2:J1771 | D10: POWER(H2, 2) | E10: Col H (Residual) | F10: Squared error (e^2)
B11: Train_Cand_15 | C11: K10:K17 | D11: AVERAGE(I2:I1771), SQRT(K13), 1-K11/K12 | E11: Cols H..J (Errors) | F11: Training summary metrics: MAE, RMSE, SSE, SST, R2, Adj R2
B12: Val_Cand_15_Winner_Watershed | C12: G2:G457 | D12: Train_Cand_15!$K$2 + Train_Cand_15!$K$3*C2 + ... | E12: Validation Cols C..F, Betas | F12: Out-of-sample prediction using Training LINEST betas
B13: Val_Cand_15_Winner_Watershed | C13: H2:J457 | D13: B2-G2, ABS(H2), POWER(H2,2) | E13: Col B, Col G | F13: Out-of-sample residual, absolute error, squared error
B14: Val_Cand_15_Winner_Watershed | C14: L2:L8 | D14: AVERAGE(I2:I457), SQRT(AVERAGE(J2:J457)) | E14: Cols I, J | F14: Validation MAE, RMSE, Bias, and R2 summary metrics
B15: Val_Pairwise_456_Dates | C15: O2:R457 | D15: Pred_C15 (Col O), Res_C15 (Col P), AbsErr_C15 (Col Q), SqErr_C15 (Col R) | E15: 456 Common Validation Dates | F15: Repaired Candidate 15 prediction and error columns
B16: Val_Pairwise_456_Dates | C16: W10:W16 | D16: AVERAGE(Q2:Q457), SQRT(AVERAGE(R2:R457)), AVERAGE(P2:P457) | E16: Cols P, Q, R | F16: Repaired Candidate 15 summary formulas (MAE, RMSE, Bias, R2)
... B18: Pairwise_Matrix_Admissible | C18: H6:P96 | D18: H6 - I6, IF(J6<0, D6, F6) | E18: Cols F, G | F18: Pairwise MAE/RMSE differentials and Condorcet winner logic

Sheet Daily_Data_2016_2023
A1: Date | B1: Sto_Nino_WL_DailyMax | C1: Sto_t_1 | D1: Sto_t_3 | E1: Oro_Rain_DailySum | F1: Oro_t_1 | G1: Campana_Rain_DailySum | H1: Campana_t_1 | I1: Boso_Rain_DailySum | J1: Boso_t_1 | K1: Aries_Rain_DailySum | L1: Aries_t_1
A2: 42370 | B2: 12.31 | E2: 1 | G2: 5 | I2: 2 | K2: 1
A3: 42371 | B3: 12.32 | C3: 12.31 | E3: 1 | F3: 1 | G3: 6 | H3: 5 | I3: 6 | J3: 2 | K3: 2 | L3: 1
A4: 42372 | B4: 12.28 | C4: 12.32 | E4: 0 | F4: 1 | G4: 0 | H4: 6 | I4: 0 | J4: 6 | K4: 0 | L4: 2
A5: 42373 | C5: 12.28 | D5: 12.31 | E5: 0 | F5: 0 | G5: 0 | H5: 0 | I5: 0 | J5: 0 | K5: 0 | L5: 0
A6: 42374 | B6: 12.16 | D6: 12.32 | E6: 0 | F6: 0 | G6: 0 | H6: 0 | I6: 0 | J6: 0 | K6: 0 | L6: 0
A7: 42375 | C7: 12.16 | D7: 12.28 | E7: 0 | F7: 0 | G7: 0 | H7: 0 | I7: 0 | J7: 0 | K7: 0 | L7: 0
A8: 42376 | E8: 0 | F8: 0 | G8: 0 | H8: 0 | I8: 0 | J8: 0 | K8: 1 | L8: 0
A9: 42377 | D9: 12.16 | E9: 0 | F9: 0 | G9: 0 | H9: 0 | I9: 0 | J9: 0 | K9: 0 | L9: 1
A10: 42378 | B10: 12.08 | E10: 0 | F10: 0 | G10: 0 | H10: 0 | I10: 0 | J10: 0 | K10: 0 | L10: 0
A11: 42379 | B11: 12.07 | C11: 12.08 | E11: 0 | F11: 0 | G11: 0 | H11: 0 | I11: 0 | J11: 0 | K11: 0 | L11: 0
A12: 42380 | B12: 12.06 | C12: 12.07 | E12: 0 | F12: 0 | G12: 0 | H12: 0 | I12: 0 | J12: 0 | K12: 0 | L12: 0
A13: 42381 | B13: 12.14 | C13: 12.06 | D13: 12.08 | E13: 0 | F13: 0 | G13: 0 | H13: 0 | I13: 16 | J13: 0 | K13: 0 | L13: 0
A14: 42382 | B14: 12.12 | C14: 12.14 | D14: 12.07 | E14: 0 | F14: 0 | G14: 0 | H14: 0 | I14: 0 | J14: 16 | K14: 0 | L14: 0
A15: 42383 | B15: 12.03 | C15: 12.12 | D15: 12.06 | E15: 0 | F15: 0 | G15: 0 | H15: 0 | I15: 0 | J15: 0 | K15: 0 | L15: 0
A16: 42384 | B16: 12.01 | C16: 12.03 | D16: 12.14 | E16: 0 | F16: 0 | G16: 0 | H16: 0 | I16: 0 | J16: 0 | K16: 0 | L16: 0
A17: 42385 | B17: 12 | C17: 12.01 | D17: 12.12 | E17: 0 | F17: 0 | G17: 0 | H17: 0 | I17: 0 | J17: 0 | K17: 0 | L17: 0
A18: 42386 | B18: 12 | C18: 12 | D18: 12.03 | E18: 0 | F18: 0 | G18: 0 | H18: 0 | I18: 0 | J18: 0 | K18: 0 | L18: 0
A19: 42387 | B19: 11.99 | C19: 12 | D19: 12.01 | E19: 0 | F19: 0 | G19: 0 | H19: 0 | I19: 0 | J19: 0 | K19: 0 | L19: 0
A20: 42388 | B20: 11.98 | C20: 11.99 | D20: 12 | E20: 0 | F20: 0 | G20: 0 | H20: 0 | I20: 0 | J20: 0 | K20: 0 | L20: 0
A21: 42389 | B21: 11.97 | C21: 11.98 | D21: 12 | E21: 0 | F21: 0 | G21: 0 | H21: 0 | I21: 0 | J21: 0 | K21: 0 | L21: 0
A22: 42390 | C22: 11.97 | D22: 11.99 | E22: 0 | F22: 0 | G22: 0 | H22: 0 | I22: 0 | J22: 0 | K22: 0 | L22: 0
A23: 42391 | B23: 11.96 | D23: 11.98 | E23: 0 | F23: 0 | G23: 0 | H23: 0 | I23: 0 | J23: 0 | K23: 0 | L23: 0
A24: 42392 | B24: 11.95 | C24: 11.96 | D24: 11.97 | E24: 0 | F24: 0 | G24: 1 | H24: 0 | I24: 0 | J24: 0 | K24: 0 | L24: 0
A25: 42393 | B25: 11.95 | C25: 11.95 | E25: 0 | F25: 0 | G25: 0 | H25: 1 | I25: 0 | J25: 0 | K25: 0 | L25: 0
A26: 42394 | B26: 11.95 | C26: 11.95 | D26: 11.96 | E26: 0 | F26: 0 | G26: 0 | H26: 0 | I26: 0 | J26: 0 | K26: 0 | L26: 0
A27: 42395 | B27: 11.95 | C27: 11.95 | D27: 11.95 | E27: 0 | F27: 0 | G27: 1 | H27: 0 | I27: 0 | J27: 0 | K27: 0 | L27: 0
A28: 42396 | B28: 11.91 | C28: 11.95 | D28: 11.95 | E28: 0 | F28: 0 | G28: 0 | H28: 1 | I28: 0 | J28: 0 | K28: 0 | L28: 0
A29: 42397 | B29: 11.92 | C29: 11.91 | D29: 11.95 | E29: 0 | F29: 0 | G29: 0 | H29: 0 | I29: 0 | J29: 0 | K29: 0 | L29: 0
A30: 42398 | B30: 11.92 | C30: 11.92 | D30: 11.95 | E30: 0 | F30: 0 | G30: 0 | H30: 0 | I30: 0 | J30: 0 | K30: 0 | L30: 0
A31: 42399 | B31: 11.94 | C31: 11.92 | D31: 11.91 | E31: 0 | F31: 0 | G31: 0 | H31: 0 | I31: 0 | J31: 0 | K31: 0 | L31: 0
A32: 42400 | B32: 11.95 | C32: 11.94 | D32: 11.92 | E32: 0 | F32: 0 | G32: 0 | H32: 0 | I32: 0 | J32: 0 | K32: 0 | L32: 0
A33: 42401 | B33: 11.92 | C33: 11.95 | D33: 11.92 | E33: 0 | F33: 0 | G33: 0 | H33: 0 | I33: 0 | J33: 0 | K33: 0 | L33: 0
A34: 42402 | B34: 11.91 | C34: 11.92 | D34: 11.94 | E34: 0 | F34: 0 | G34: 0 | H34: 0 | I34: 0 | J34: 0 | K34: 0 | L34: 0
A35: 42403 | B35: 11.91 | C35: 11.91 | D35: 11.95 | E35: 0 | F35: 0 | G35: 0 | H35: 0 | I35: 0 | J35: 0 | K35: 0 | L35: 0
A36: 42404 | B36: 11.92 | C36: 11.91 | D36: 11.92 | E36: 2 | F36: 0 | G36: 0 | H36: 0 | I36: 0 | J36: 0 | K36: 0 | L36: 0
A37: 42405 | B37: 11.92 | C37: 11.92 | D37: 11.91 | E37: 0 | F37: 2 | G37: 1 | H37: 0 | I37: 2 | J37: 0 | K37: 0 | L37: 0
... A121: 42489 | B121: 11.39 | C121: 11.87 | D121: 11.87 | E121: 0 | F121: 0 | G121: 0 | H121: 0 | I121: 0 | J121: 0 | K121: 0 | L121: 0
A122: 42490 | B122: 11.39 | C122: 11.39 | D122: 11.87 | F122: 0 | H122: 0 | J122: 0 | L122: 0
A123: 42491 | B123: 11.39 | C123: 11.39 | D123: 11.87 | E123: 0 | G123: 0 | I123: 0 | K123: 0
...

Sheet Train_Cand_10
A1: Date | B1: Actual_Y | C1: Sto_Nino_DailyMaxWL_t_1 | D1: Sto_Nino_DailyMaxWL_t_3 | E1: Mt_Oro_Rain_t_1 | F1: Pred_Y_Formula | G1: Residual_Formula | H1: Abs_Error_Formula | I1: Sq_Error_Formula | K1: COEFFICIENT | L1: EXCEL LINEST FORMULA
A2: 42381 | B2: 12.14 | C2: 12.06 | D2: 12.08 | E2: 0 | F2: =$L$2 + $L$3*C2 + $L$4*D2 + $L$5*E2 -> 11.955061 | G2: =B2 - F2 -> 0.18493865 | H2: =ABS(G2) -> 0.18493865 | I2: =POWER(G2, 2) -> 0.034202305 | K2: Intercept (beta_0) | L2: =INDEX(LINEST(B2:B2111, C2:E2111, TRUE, FALSE), 1, 4) -> 5.2034777
A3: 42382 | B3: 12.12 | C3: 12.14 | D3: 12.07 | E3: 0 | F3: =$L$2 + $L$3*C3 + $L$4*D3 + $L$5*E3 -> 11.977474 | G3: =B3 - F3 -> 0.14252601 | H3: =ABS(G3) -> 0.14252601 | I3: =POWER(G3, 2) -> 0.020313662 | K3: Sto_Nino_DailyMaxWL_t_1 (beta_1) | L3: =INDEX(LINEST(B2:B2111, C2:E2111, TRUE, FALSE), 1, 3) -> 0.31118732
A4: 42383 | B4: 12.03 | C4: 12.12 | D4: 12.06 | E4: 0 | F4: =$L$2 + $L$3*C4 + $L$4*D4 + $L$5*E4 -> 11.968768 | G4: =B4 - F4 -> 0.061232091 | H4: =ABS(G4) -> 0.061232091 | I4: =POWER(G4, 2) -> 0.0037493689 | K4: Sto_Nino_DailyMaxWL_t_3 (beta_2) | L4: =INDEX(LINEST(B2:B2111, C2:E2111, TRUE, FALSE), 1, 2) -> 0.24823382
A5: 42384 | B5: 12.01 | C5: 12.03 | D5: 12.14 | E5: 0 | F5: =$L$2 + $L$3*C5 + $L$4*D5 + $L$5*E5 -> 11.96062 | G5: =B5 - F5 -> 0.049380243 | H5: =ABS(G5) -> 0.049380243 | I5: =POWER(G5, 2) -> 0.0024384084 | K5: Mt_Oro_Rain_t_1 (beta_3) | L5: =INDEX(LINEST(B2:B2111, C2:E2111, TRUE, FALSE), 1, 1) -> 0.015296946
A6: 42385 | B6: 12 | C6: 12.01 | D6: 12.12 | E6: 0 | F6: =$L$2 + $L$3*C6 + $L$4*D6 + $L$5*E6 -> 11.949431 | G6: =B6 - F6 -> 0.050568666 | H6: =ABS(G6) -> 0.050568666 | I6: =POWER(G6, 2) -> 0.00255719
A7: 42386 | B7: 12 | C7: 12 | D7: 12.03 | E7: 0 | F7: =$L$2 + $L$3*C7 + $L$4*D7 + $L$5*E7 -> 11.923978 | G7: =B7 - F7 -> 0.076021583 | H7: =ABS(G7) -> 0.076021583 | I7: =POWER(G7, 2) -> 0.0057792811 | K7: TRAINING METRIC | L7: EXCEL FORMULA VALUE
A8: 42387 | B8: 11.99 | C8: 12 | D8: 12.01 | E8: 0 | F8: =$L$2 + $L$3*C8 + $L$4*D8 + $L$5*E8 -> 11.919014 | G8: =B8 - F8 -> 0.07098626 | H8: =ABS(G8) -> 0.07098626 | I8: =POWER(G8, 2) -> 0.0050390491 | K8: Training N | L8: =COUNT(B2:B2111) -> 2110
A9: 42388 | B9: 11.98 | C9: 11.99 | D9: 12 | E9: 0 | F9: =$L$2 + $L$3*C9 + $L$4*D9 + $L$5*E9 -> 11.91342 | G9: =B9 - F9 -> 0.066580471 | H9: =ABS(G9) -> 0.066580471 | I9: =POWER(G9, 2) -> 0.0044329591 | K9: Predictors (K) | L9: 3
A10: 42389 | B10: 11.97 | C10: 11.98 | D10: 12 | E10: 0 | F10: =$L$2 + $L$3*C10 + $L$4*D10 + $L$5*E10 -> 11.910308 | G10: =B10 - F10 -> 0.059692344 | H10: =ABS(G10) -> 0.059692344 | I10: =POWER(G10, 2) -> 0.003563176 | K10: SSE | L10: =SUM(I2:I2111) -> 19438.991
A11: 42392 | B11: 11.95 | C11: 11.96 | D11: 11.97 | E11: 0 | F11: =$L$2 + $L$3*C11 + $L$4*D11 + $L$5*E11 -> 11.896637 | G11: =B11 - F11 -> 0.053363105 | H11: =ABS(G11) -> 0.053363105 | I11: =POWER(G11, 2) -> 0.002847621 | K11: SST | L11: =DEVSQ(B2:B2111) -> 25343.572
A12: 42394 | B12: 11.95 | C12: 11.95 | D12: 11.96 | E12: 0 | F12: =$L$2 + $L$3*C12 + $L$4*D12 + $L$5*E12 -> 11.891043 | G12: =B12 - F12 -> 0.058957317 | H12: =ABS(G12) -> 0.058957317 | I12: =POWER(G12, 2) -> 0.0034759652 | K12: MSE | L12: =L10/(L8 - L9 - 1) -> 9.23029
A13: 42395 | B13: 11.95 | C13: 11.95 | D13: 11.95 | E13: 0 | F13: =$L$2 + $L$3*C13 + $L$4*D13 + $L$5*E13 -> 11.88856 | G13: =B13 - F13 -> 0.061439655 | H13: =ABS(G13) -> 0.061439655 | I13: =POWER(G13, 2) -> 0.0037748312 | K13: RMSE (m) | L13: =SQRT(L12) -> 3.0381392
A14: 42396 | B14: 11.91 | C14: 11.95 | D14: 11.95 | E14: 0 | F14: =$L$2 + $L$3*C14 + $L$4*D14 + $L$5*E14 -> 11.88856 | G14: =B14 - F14 -> 0.021439655 | H14: =ABS(G14) -> 0.021439655 | I14: =POWER(G14, 2) -> 0.0004596588 | K14: MAE (m) | L14: =AVERAGE(H2:H2111) -> 0.68010816
A15: 42397 | B15: 11.92 | C15: 11.91 | D15: 11.95 | E15: 0 | F15: =$L$2 + $L$3*C15 + $L$4*D15 + $L$5*E15 -> 11.876113 | G15: =B15 - F15 -> 0.043887148 | H15: =ABS(G15) -> 0.043887148 | I15: =POWER(G15, 2) -> 0.0019260817 | K15: Training R2 | L15: =1 - (L10 / L11) -> 0.23298142
A16: 42398 | B16: 11.92 | C16: 11.92 | D16: 11.95 | E16: 0 | F16: =$L$2 + $L$3*C16 + $L$4*D16 + $L$5*E16 -> 11.879225 | G16: =B16 - F16 -> 0.040775274 | H16: =ABS(G16) -> 0.040775274 | I16: =POWER(G16, 2) -> 0.001662623 | K16: Training Adj R2 | L16: =1 - ((1 - L15)*(L8 - 1)/(L8 - L9 - 1)) -> 0.2318888
A17: 42399 | B17: 11.94 | C17: 11.92 | D17: 11.91 | E17: 0 | F17: =$L$2 + $L$3*C17 + $L$4*D17 + $L$5*E17 -> 11.869295 | G17: =B17 - F17 -> 0.070704627 | H17: =ABS(G17) -> 0.070704627 | I17: =POWER(G17, 2) -> 0.0049991443
A18: 42400 | B18: 11.95 | C18: 11.94 | D18: 11.92 | E18: 0 | F18: =$L$2 + $L$3*C18 + $L$4*D18 + $L$5*E18 -> 11.878001 | G18: =B18 - F18 -> 0.071998543 | H18: =ABS(G18) -> 0.071998543 | I18: =POWER(G18, 2) -> 0.0051837901
A19: 42401 | B19: 11.92 | C19: 11.95 | D19: 11.92 | E19: 0 | F19: =$L$2 + $L$3*C19 + $L$4*D19 + $L$5*E19 -> 11.881113 | G19: =B19 - F19 -> 0.038886669 | H19: =ABS(G19) -> 0.038886669 | I19: =POWER(G19, 2) -> 0.0015121731
A20: 42402 | B20: 11.91 | C20: 11.92 | D20: 11.94 | E20: 0 | F20: =$L$2 + $L$3*C20 + $L$4*D20 + $L$5*E20 -> 11.876742 | G20: =B20 - F20 -> 0.033257613 | H20: =ABS(G20) -> 0.033257613 | I20: =POWER(G20, 2) -> 0.0011060688
A21: 42403 | B21: 11.91 | C21: 11.91 | D21: 11.95 | E21: 0 | F21: =$L$2 + $L$3*C21 + $L$4*D21 + $L$5*E21 -> 11.876113 | G21: =B21 - F21 -> 0.033887148 | H21: =ABS(G21) -> 0.033887148 | I21: =POWER(G21, 2) -> 0.0011483388
A22: 42404 | B22: 11.92 | C22: 11.91 | D22: 11.92 | E22: 0 | F22: =$L$2 + $L$3*C22 + $L$4*D22 + $L$5*E22 -> 11.868666 | G22: =B22 - F22 -> 0.051334162 | H22: =ABS(G22) -> 0.051334162 | I22: =POWER(G22, 2) -> 0.0026351962
A23: 42405 | B23: 11.92 | C23: 11.92 | D23: 11.91 | E23: 2 | F23: =$L$2 + $L$3*C23 + $L$4*D23 + $L$5*E23 -> 11.899889 | G23: =B23 - F23 -> 0.020110734 | H23: =ABS(G23) -> 0.020110734 | I23: =POWER(G23, 2) -> 0.00040444163
A24: 42406 | B24: 11.96 | C24: 11.92 | D24: 11.91 | E24: 0 | F24: =$L$2 + $L$3*C24 + $L$4*D24 + $L$5*E24 -> 11.869295 | G24: =B24 - F24 -> 0.090704627 | H24: =ABS(G24) -> 0.090704627 | I24: =POWER(G24, 2) -> 0.0082273294
A25: 42407 | B25: 11.96 | C25: 11.96 | D25: 11.92 | E25: 1 | F25: =$L$2 + $L$3*C25 + $L$4*D25 + $L$5*E25 -> 11.899522 | G25: =B25 - F25 -> 0.06047785 | H25: =ABS(G25) -> 0.06047785 | I25: =POWER(G25, 2) -> 0.0036575703
A26: 42408 | B26: 11.93 | C26: 11.96 | D26: 11.92 | E26: 0 | F26: =$L$2 + $L$3*C26 + $L$4*D26 + $L$5*E26 -> 11.884225 | G26: =B26 - F26 -> 0.045774796 | H26: =ABS(G26) -> 0.045774796 | I26: =POWER(G26, 2) -> 0.002095332
A27: 42409 | B27: 11.92 | C27: 11.93 | D27: 11.96 | E27: 0 | F27: =$L$2 + $L$3*C27 + $L$4*D27 + $L$5*E27 -> 11.884819 | G27: =B27 - F27 -> 0.035181063 | H27: =ABS(G27) -> 0.035181063 | I27: =POWER(G27, 2) -> 0.0012377072
A28: 42410 | B28: 11.91 | C28: 11.92 | D28: 11.96 | E28: 0 | F28: =$L$2 + $L$3*C28 + $L$4*D28 + $L$5*E28 -> 11.881707 | G28: =B28 - F28 -> 0.028292936 | H28: =ABS(G28) -> 0.028292936 | I28: =POWER(G28, 2) -> 0.00080049024
... A2111: 44707 | B2111: 11.96 | C2111: 11.56 | D2111: 12.46 | E2111: 0 | F2111: =$L$2 + $L$3*C2111 + $L$4*D2111 + $L$5*E2111 -> 11.893797 | G2111: =B2111 - F2111 -> 0.06620346 | H2111: =ABS(G2111) -> 0.06620346 | I2111: =POWER(G2111, 2) -> 0.0043828981

Sheet Train_Cand_11
A1: Date | B1: Actual_Y | C1: Sto_Nino_DailyMaxWL_t_1 | D1: Sto_Nino_DailyMaxWL_t_3 | E1: Mt_Campana_Rain_t_1 | F1: Pred_Y_Formula | G1: Residual_Formula | H1: Abs_Error_Formula | I1: Sq_Error_Formula | K1: COEFFICIENT | L1: EXCEL LINEST FORMULA
A2: 42381 | B2: 12.14 | C2: 12.06 | D2: 12.08 | E2: 0 | F2: =$L$2 + $L$3*C2 + $L$4*D2 + $L$5*E2 -> 12.11241 | G2: =B2 - F2 -> 0.027590491 | H2: =ABS(G2) -> 0.027590491 | I2: =POWER(G2, 2) -> 0.00076123517 | K2: Intercept (beta_0) | L2: =INDEX(LINEST(B2:B1806, C2:E1806, TRUE, FALSE), 1, 4) -> 3.6762724
A3: 42382 | B3: 12.12 | C3: 12.14 | D3: 12.07 | E3: 0 | F3: =$L$2 + $L$3*C3 + $L$4*D3 + $L$5*E3 -> 12.160829 | G3: =B3 - F3 -> -0.040828909 | H3: =ABS(G3) -> 0.040828909 | I3: =POWER(G3, 2) -> 0.0016669998 | K3: Sto_Nino_DailyMaxWL_t_1 (beta_1) | L3: =INDEX(LINEST(B2:B1806, C2:E1806, TRUE, FALSE), 1, 3) -> 0.61570167
A4: 42383 | B4: 12.03 | C4: 12.12 | D4: 12.06 | E4: 0 | F4: =$L$2 + $L$3*C4 + $L$4*D4 + $L$5*E4 -> 12.147678 | G4: =B4 - F4 -> -0.11767814 | H4: =ABS(G4) -> 0.11767814 | I4: =POWER(G4, 2) -> 0.013848145 | K4: Sto_Nino_DailyMaxWL_t_3 (beta_2) | L4: =INDEX(LINEST(B2:B1806, C2:E1806, TRUE, FALSE), 1, 2) -> 0.083673429
A5: 42384 | B5: 12.01 | C5: 12.03 | D5: 12.14 | E5: 0 | F5: =$L$2 + $L$3*C5 + $L$4*D5 + $L$5*E5 -> 12.098959 | G5: =B5 - F5 -> -0.088958865 | H5: =ABS(G5) -> 0.088958865 | I5: =POWER(G5, 2) -> 0.0079136797 | K5: Mt_Campana_Rain_t_1 (beta_3) | L5: =INDEX(LINEST(B2:B1806, C2:E1806, TRUE, FALSE), 1, 1) -> 0.0090968674
A6: 42385 | B6: 12 | C6: 12.01 | D6: 12.12 | E6: 0 | F6: =$L$2 + $L$3*C6 + $L$4*D6 + $L$5*E6 -> 12.084971 | G6: =B6 - F6 -> -0.084971363 | H6: =ABS(G6) -> 0.084971363 | I6: =POWER(G6, 2) -> 0.0072201326
A7: 42386 | B7: 12 | C7: 12 | D7: 12.03 | E7: 0 | F7: =$L$2 + $L$3*C7 + $L$4*D7 + $L$5*E7 -> 12.071284 | G7: =B7 - F7 -> -0.071283738 | H7: =ABS(G7) -> 0.071283738 | I7: =POWER(G7, 2) -> 0.0050813713 | K7: TRAINING METRIC | L7: EXCEL FORMULA VALUE
A8: 42387 | B8: 11.99 | C8: 12 | D8: 12.01 | E8: 0 | F8: =$L$2 + $L$3*C8 + $L$4*D8 + $L$5*E8 -> 12.06961 | G8: =B8 - F8 -> -0.079610269 | H8: =ABS(G8) -> 0.079610269 | I8: =POWER(G8, 2) -> 0.006337795 | K8: Training N | L8: =COUNT(B2:B1806) -> 1805
A9: 42388 | B9: 11.98 | C9: 11.99 | D9: 12 | E9: 0 | F9: =$L$2 + $L$3*C9 + $L$4*D9 + $L$5*E9 -> 12.062617 | G9: =B9 - F9 -> -0.082616518 | H9: =ABS(G9) -> 0.082616518 | I9: =POWER(G9, 2) -> 0.0068254891 | K9: Predictors (K) | L9: 3
A10: 42389 | B10: 11.97 | C10: 11.98 | D10: 12 | E10: 0 | F10: =$L$2 + $L$3*C10 + $L$4*D10 + $L$5*E10 -> 12.05646 | G10: =B10 - F10 -> -0.086459502 | H10: =ABS(G10) -> 0.086459502 | I10: =POWER(G10, 2) -> 0.0074752454 | K10: SSE | L10: =SUM(I2:I1806) -> 1016.5512
A11: 42392 | B11: 11.95 | C11: 11.96 | D11: 11.97 | E11: 0 | F11: =$L$2 + $L$3*C11 + $L$4*D11 + $L$5*E11 -> 12.041635 | G11: =B11 - F11 -> -0.091635265 | H11: =ABS(G11) -> 0.091635265 | I11: =POWER(G11, 2) -> 0.0083970219 | K11: SST | L11: =DEVSQ(B2:B1806) -> 1999.1896
A12: 42394 | B12: 11.95 | C12: 11.95 | D12: 11.96 | E12: 0 | F12: =$L$2 + $L$3*C12 + $L$4*D12 + $L$5*E12 -> 12.034642 | G12: =B12 - F12 -> -0.084641514 | H12: =ABS(G12) -> 0.084641514 | I12: =POWER(G12, 2) -> 0.007164186 | K12: MSE | L12: =L10/(L8 - L9 - 1) -> 0.56443711
A13: 42395 | B13: 11.95 | C13: 11.95 | D13: 11.95 | E13: 0 | F13: =$L$2 + $L$3*C13 + $L$4*D13 + $L$5*E13 -> 12.033805 | G13: =B13 - F13 -> -0.08380478 | H13: =ABS(G13) -> 0.08380478 | I13: =POWER(G13, 2) -> 0.0070232412 | K13: RMSE (m) | L13: =SQRT(L12) -> 0.7512903
A14: 42396 | B14: 11.91 | C14: 11.95 | D14: 11.95 | E14: 1 | F14: =$L$2 + $L$3*C14 + $L$4*D14 + $L$5*E14 -> 12.042902 | G14: =B14 - F14 -> -0.13290165 | H14: =ABS(G14) -> 0.13290165 | I14: =POWER(G14, 2) -> 0.017662848 | K14: MAE (m) | L14: =AVERAGE(H2:H1806) -> 0.27669889
A15: 42397 | B15: 11.92 | C15: 11.91 | D15: 11.95 | E15: 0 | F15: =$L$2 + $L$3*C15 + $L$4*D15 + $L$5*E15 -> 12.009177 | G15: =B15 - F15 -> -0.089176713 | H15: =ABS(G15) -> 0.089176713 | I15: =POWER(G15, 2) -> 0.0079524862 | K15: Training R2 | L15: =1 - (L10 / L11) -> 0.49151834
A16: 42398 | B16: 11.92 | C16: 11.92 | D16: 11.95 | E16: 0 | F16: =$L$2 + $L$3*C16 + $L$4*D16 + $L$5*E16 -> 12.015334 | G16: =B16 - F16 -> -0.09533373 | H16: =ABS(G16) -> 0.09533373 | I16: =POWER(G16, 2) -> 0.0090885201 | K16: Training Adj R2 | L16: =1 - ((1 - L15)*(L8 - 1)/(L8 - L9 - 1)) -> 0.49067134
A17: 42399 | B17: 11.94 | C17: 11.92 | D17: 11.91 | E17: 0 | F17: =$L$2 + $L$3*C17 + $L$4*D17 + $L$5*E17 -> 12.011987 | G17: =B17 - F17 -> -0.071986793 | H17: =ABS(G17) -> 0.071986793 | I17: =POWER(G17, 2) -> 0.0051820984
A18: 42400 | B18: 11.95 | C18: 11.94 | D18: 11.92 | E18: 0 | F18: =$L$2 + $L$3*C18 + $L$4*D18 + $L$5*E18 -> 12.025138 | G18: =B18 - F18 -> -0.075137561 | H18: =ABS(G18) -> 0.075137561 | I18: =POWER(G18, 2) -> 0.005645653
A19: 42401 | B19: 11.92 | C19: 11.95 | D19: 11.92 | E19: 0 | F19: =$L$2 + $L$3*C19 + $L$4*D19 + $L$5*E19 -> 12.031295 | G19: =B19 - F19 -> -0.11129458 | H19: =ABS(G19) -> 0.11129458 | I19: =POWER(G19, 2) -> 0.012386483
A20: 42402 | B20: 11.91 | C20: 11.92 | D20: 11.94 | E20: 0 | F20: =$L$2 + $L$3*C20 + $L$4*D20 + $L$5*E20 -> 12.014497 | G20: =B20 - F20 -> -0.104497 | H20: =ABS(G20) -> 0.104497 | I20: =POWER(G20, 2) -> 0.010919622
A21: 42403 | B21: 11.91 | C21: 11.91 | D21: 11.95 | E21: 0 | F21: =$L$2 + $L$3*C21 + $L$4*D21 + $L$5*E21 -> 12.009177 | G21: =B21 - F21 -> -0.099176713 | H21: =ABS(G21) -> 0.099176713 | I21: =POWER(G21, 2) -> 0.0098360205
A22: 42404 | B22: 11.92 | C22: 11.91 | D22: 11.92 | E22: 0 | F22: =$L$2 + $L$3*C22 + $L$4*D22 + $L$5*E22 -> 12.006667 | G22: =B22 - F22 -> -0.086666511 | H22: =ABS(G22) -> 0.086666511 | I22: =POWER(G22, 2) -> 0.0075110841
A23: 42405 | B23: 11.92 | C23: 11.92 | D23: 11.91 | E23: 0 | F23: =$L$2 + $L$3*C23 + $L$4*D23 + $L$5*E23 -> 12.011987 | G23: =B23 - F23 -> -0.091986793 | H23: =ABS(G23) -> 0.091986793 | I23: =POWER(G23, 2) -> 0.0084615701
A24: 42406 | B24: 11.96 | C24: 11.92 | D24: 11.91 | E24: 1 | F24: =$L$2 + $L$3*C24 + $L$4*D24 + $L$5*E24 -> 12.021084 | G24: =B24 - F24 -> -0.06108366 | H24: =ABS(G24) -> 0.06108366 | I24: =POWER(G24, 2) -> 0.0037312136
A25: 42407 | B25: 11.96 | C25: 11.96 | D25: 11.92 | E25: 2 | F25: =$L$2 + $L$3*C25 + $L$4*D25 + $L$5*E25 -> 12.055645 | G25: =B25 - F25 -> -0.095645329 | H25: =ABS(G25) -> 0.095645329 | I25: =POWER(G25, 2) -> 0.0091480289
A26: 42408 | B26: 11.93 | C26: 11.96 | D26: 11.92 | E26: 0 | F26: =$L$2 + $L$3*C26 + $L$4*D26 + $L$5*E26 -> 12.037452 | G26: =B26 - F26 -> -0.10745159 | H26: =ABS(G26) -> 0.10745159 | I26: =POWER(G26, 2) -> 0.011545845
A27: 42409 | B27: 11.92 | C27: 11.93 | D27: 11.96 | E27: 0 | F27: =$L$2 + $L$3*C27 + $L$4*D27 + $L$5*E27 -> 12.022327 | G27: =B27 - F27 -> -0.10232748 | H27: =ABS(G27) -> 0.10232748 | I27: =POWER(G27, 2) -> 0.010470913
A28: 42410 | B28: 11.91 | C28: 11.92 | D28: 11.96 | E28: 0 | F28: =$L$2 + $L$3*C28 + $L$4*D28 + $L$5*E28 -> 12.01617 | G28: =B28 - F28 -> -0.10617046 | H28: =ABS(G28) -> 0.10617046 | I28: =POWER(G28, 2) -> 0.011272168
... A1806: 44707 | B1806: 11.96 | C1806: 11.56 | D1806: 12.46 | E1806: 0 | F1806: =$L$2 + $L$3*C1806 + $L$4*D1806 + $L$5*E1806 -> 11.836355 | G1806: =B1806 - F1806 -> 0.12364542 | H1806: =ABS(G1806) -> 0.12364542 | I1806: =POWER(G1806, 2) -> 0.01528819

Sheet Train_Cand_15
A1: Date | B1: Actual_Y | C1: Sto_Nino_DailyMaxWL_t_1 | D1: Sto_Nino_DailyMaxWL_t_3 | E1: Mt_Oro_Rain_t_1 | F1: Mt_Campana_Rain_t_1 | G1: Pred_Y_Formula | H1: Residual_Formula | I1: Abs_Error_Formula | J1: Sq_Error_Formula | L1: COEFFICIENT | M1: EXCEL LINEST FORMULA
A2: 42381 | B2: 12.14 | C2: 12.06 | D2: 12.08 | E2: 0 | F2: 0 | G2: =$M$2 + $M$3*C2 + $M$4*D2 + $M$5*E2 + $M$6*F2 -> 12.104438 | H2: =B2 - G2 -> 0.035562111 | I2: =ABS(H2) -> 0.035562111 | J2: =POWER(H2, 2) -> 0.0012646637 | L2: Intercept (beta_0) | M2: =INDEX(LINEST(B2:B1771, C2:F1771, TRUE, FALSE), 1, 5) -> 3.8399076
A3: 42382 | B3: 12.12 | C3: 12.14 | D3: 12.07 | E3: 0 | F3: 0 | G3: =$M$2 + $M$3*C3 + $M$4*D3 + $M$5*E3 + $M$6*F3 -> 12.151828 | H3: =B3 - G3 -> -0.031828162 | I3: =ABS(H3) -> 0.031828162 | J3: =POWER(H3, 2) -> 0.0010130319 | L3: Sto_Nino_DailyMaxWL_t_1 (beta_1) | M3: =INDEX(LINEST(B2:B1771, C2:F1771, TRUE, FALSE), 1, 4) -> 0.6026861
A4: 42383 | B4: 12.03 | C4: 12.12 | D4: 12.06 | E4: 0 | F4: 0 | G4: =$M$2 + $M$3*C4 + $M$4*D4 + $M$5*E4 + $M$6*F4 -> 12.13895 | H4: =B4 - G4 -> -0.10894982 | I4: =ABS(H4) -> 0.10894982 | J4: =POWER(H4, 2) -> 0.011870064 | L4: Sto_Nino_DailyMaxWL_t_3 (beta_2) | M4: =INDEX(LINEST(B2:B1771, C2:F1771, TRUE, FALSE), 1, 3) -> 0.082461583
A5: 42384 | B5: 12.01 | C5: 12.03 | D5: 12.14 | E5: 0 | F5: 0 | G5: =$M$2 + $M$3*C5 + $M$4*D5 + $M$5*E5 + $M$6*F5 -> 12.091305 | H5: =B5 - G5 -> -0.081305001 | I5: =ABS(H5) -> 0.081305001 | J5: =POWER(H5, 2) -> 0.0066105032 | L5: Mt_Oro_Rain_t_1 (beta_3) | M5: =INDEX(LINEST(B2:B1771, C2:F1771, TRUE, FALSE), 1, 2) -> 0.0032509556
A6: 42385 | B6: 12 | C6: 12.01 | D6: 12.12 | E6: 0 | F6: 0 | G6: =$M$2 + $M$3*C6 + $M$4*D6 + $M$5*E6 + $M$6*F6 -> 12.077602 | H6: =B6 - G6 -> -0.077602047 | I6: =ABS(H6) -> 0.077602047 | J6: =POWER(H6, 2) -> 0.0060220777 | L6: Mt_Campana_Rain_t_1 (beta_4) | M6: =INDEX(LINEST(B2:B1771, C2:F1771, TRUE, FALSE), 1, 1) -> 0.0072971849
A7: 42386 | B7: 12 | C7: 12 | D7: 12.03 | E7: 0 | F7: 0 | G7: =$M$2 + $M$3*C7 + $M$4*D7 + $M$5*E7 + $M$6*F7 -> 12.064154 | H7: =B7 - G7 -> -0.064153644 | I7: =ABS(H7) -> 0.064153644 | J7: =POWER(H7, 2) -> 0.00411569
A8: 42387 | B8: 11.99 | C8: 12 | D8: 12.01 | E8: 0 | F8: 0 | G8: =$M$2 + $M$3*C8 + $M$4*D8 + $M$5*E8 + $M$6*F8 -> 12.062504 | H8: =B8 - G8 -> -0.072504412 | I8: =ABS(H8) -> 0.072504412 | J8: =POWER(H8, 2) -> 0.0052568898 | L8: TRAINING METRIC | M8: EXCEL FORMULA VALUE
A9: 42388 | B9: 11.98 | C9: 11.99 | D9: 12 | E9: 0 | F9: 0 | G9: =$M$2 + $M$3*C9 + $M$4*D9 + $M$5*E9 + $M$6*F9 -> 12.055653 | H9: =B9 - G9 -> -0.075652935 | I9: =ABS(H9) -> 0.075652935 | J9: =POWER(H9, 2) -> 0.0057233666 | L9: Training N | M9: =COUNT(B2:B1771) -> 1770
A10: 42389 | B10: 11.97 | C10: 11.98 | D10: 12 | E10: 0 | F10: 0 | G10: =$M$2 + $M$3*C10 + $M$4*D10 + $M$5*E10 + $M$6*F10 -> 12.049626 | H10: =B10 - G10 -> -0.079626074 | I10: =ABS(H10) -> 0.079626074 | J10: =POWER(H10, 2) -> 0.0063403117 | L10: Predictors (K) | M10: 4
A11: 42392 | B11: 11.95 | C11: 11.96 | D11: 11.97 | E11: 0 | F11: 0 | G11: =$M$2 + $M$3*C11 + $M$4*D11 + $M$5*E11 + $M$6*F11 -> 12.035099 | H11: =B11 - G11 -> -0.085098505 | I11: =ABS(H11) -> 0.085098505 | J11: =POWER(H11, 2) -> 0.0072417555 | L11: SSE | M11: =SUM(J2:J1771) -> 989.61074
A12: 42394 | B12: 11.95 | C12: 11.95 | D12: 11.96 | E12: 0 | F12: 0 | G12: =$M$2 + $M$3*C12 + $M$4*D12 + $M$5*E12 + $M$6*F12 -> 12.028247 | H12: =B12 - G12 -> -0.078247028 | I12: =ABS(H12) -> 0.078247028 | J12: =POWER(H12, 2) -> 0.0061225974 | L12: SST | M12: =DEVSQ(B2:B1771) -> 1955.378
A13: 42395 | B13: 11.95 | C13: 11.95 | D13: 11.95 | E13: 0 | F13: 0 | G13: =$M$2 + $M$3*C13 + $M$4*D13 + $M$5*E13 + $M$6*F13 -> 12.027422 | H13: =B13 - G13 -> -0.077422412 | I13: =ABS(H13) -> 0.077422412 | J13: =POWER(H13, 2) -> 0.0059942299 | L13: MSE | M13: =M11/(M9 - M10 - 1) -> 0.56068597
A14: 42396 | B14: 11.91 | C14: 11.95 | D14: 11.95 | E14: 0 | F14: 1 | G14: =$M$2 + $M$3*C14 + $M$4*D14 + $M$5*E14 + $M$6*F14 -> 12.03472 | H14: =B14 - G14 -> -0.1247196 | I14: =ABS(H14) -> 0.1247196 | J14: =POWER(H14, 2) -> 0.015554978 | L14: RMSE (m) | M14: =SQRT(M13) -> 0.74878967
A15: 42397 | B15: 11.92 | C15: 11.91 | D15: 11.95 | E15: 0 | F15: 0 | G15: =$M$2 + $M$3*C15 + $M$4*D15 + $M$5*E15 + $M$6*F15 -> 12.003315 | H15: =B15 - G15 -> -0.083314968 | I15: =ABS(H15) -> 0.083314968 | J15: =POWER(H15, 2) -> 0.0069413839 | L15: MAE (m) | M15: =AVERAGE(I2:I1771) -> 0.27280371
A16: 42398 | B16: 11.92 | C16: 11.92 | D16: 11.95 | E16: 0 | F16: 0 | G16: =$M$2 + $M$3*C16 + $M$4*D16 + $M$5*E16 + $M$6*F16 -> 12.009342 | H16: =B16 - G16 -> -0.089341829 | I16: =ABS(H16) -> 0.089341829 | J16: =POWER(H16, 2) -> 0.0079819624 | L16: Training R2 | M16: =1 - (M11 / M12) -> 0.4939031
A17: 42399 | B17: 11.94 | C17: 11.92 | D17: 11.91 | E17: 0 | F17: 0 | G17: =$M$2 + $M$3*C17 + $M$4*D17 + $M$5*E17 + $M$6*F17 -> 12.006043 | H17: =B17 - G17 -> -0.066043366 | I17: =ABS(H17) -> 0.066043366 | J17: =POWER(H17, 2) -> 0.0043617262 | L17: Training Adj R2 | M17: =1 - ((1 - M16)*(M9 - 1)/(M9 - M10 - 1)) -> 0.49275614
A18: 42400 | B18: 11.95 | C18: 11.94 | D18: 11.92 | E18: 0 | F18: 0 | G18: =$M$2 + $M$3*C18 + $M$4*D18 + $M$5*E18 + $M$6*F18 -> 12.018922 | H18: =B18 - G18 -> -0.068921704 | I18: =ABS(H18) -> 0.068921704 | J18: =POWER(H18, 2) -> 0.0047502012
A19: 42401 | B19: 11.92 | C19: 11.95 | D19: 11.92 | E19: 0 | F19: 0 | G19: =$M$2 + $M$3*C19 + $M$4*D19 + $M$5*E19 + $M$6*F19 -> 12.024949 | H19: =B19 - G19 -> -0.10494856 | I19: =ABS(H19) -> 0.10494856 | J19: =POWER(H19, 2) -> 0.011014201
A20: 42402 | B20: 11.91 | C20: 11.92 | D20: 11.94 | E20: 0 | F20: 0 | G20: =$M$2 + $M$3*C20 + $M$4*D20 + $M$5*E20 + $M$6*F20 -> 12.008517 | H20: =B20 - G20 -> -0.098517213 | I20: =ABS(H20) -> 0.098517213 | J20: =POWER(H20, 2) -> 0.0097056413
A21: 42403 | B21: 11.91 | C21: 11.91 | D21: 11.95 | E21: 0 | F21: 0 | G21: =$M$2 + $M$3*C21 + $M$4*D21 + $M$5*E21 + $M$6*F21 -> 12.003315 | H21: =B21 - G21 -> -0.093314968 | I21: =ABS(H21) -> 0.093314968 | J21: =POWER(H21, 2) -> 0.0087076833
A22: 42404 | B22: 11.92 | C22: 11.91 | D22: 11.92 | E22: 0 | F22: 0 | G22: =$M$2 + $M$3*C22 + $M$4*D22 + $M$5*E22 + $M$6*F22 -> 12.000841 | H22: =B22 - G22 -> -0.080841121 | I22: =ABS(H22) -> 0.080841121 | J22: =POWER(H22, 2) -> 0.0065352868
A23: 42405 | B23: 11.92 | C23: 11.92 | D23: 11.91 | E23: 2 | F23: 0 | G23: =$M$2 + $M$3*C23 + $M$4*D23 + $M$5*E23 + $M$6*F23 -> 12.012545 | H23: =B23 - G23 -> -0.092545277 | I23: =ABS(H23) -> 0.092545277 | J23: =POWER(H23, 2) -> 0.0085646283
A24: 42406 | B24: 11.96 | C24: 11.92 | D24: 11.91 | E24: 0 | F24: 1 | G24: =$M$2 + $M$3*C24 + $M$4*D24 + $M$5*E24 + $M$6*F24 -> 12.013341 | H24: =B24 - G24 -> -0.053340551 | I24: =ABS(H24) -> 0.053340551 | J24: =POWER(H24, 2) -> 0.0028452143
A25: 42407 | B25: 11.96 | C25: 11.96 | D25: 11.92 | E25: 1 | F25: 2 | G25: =$M$2 + $M$3*C25 + $M$4*D25 + $M$5*E25 + $M$6*F25 -> 12.048821 | H25: =B25 - G25 -> -0.088820751 | I25: =ABS(H25) -> 0.088820751 | J25: =POWER(H25, 2) -> 0.0078891258
A26: 42408 | B26: 11.93 | C26: 11.96 | D26: 11.92 | E26: 0 | F26: 0 | G26: =$M$2 + $M$3*C26 + $M$4*D26 + $M$5*E26 + $M$6*F26 -> 12.030975 | H26: =B26 - G26 -> -0.10097543 | I26: =ABS(H26) -> 0.10097543 | J26: =POWER(H26, 2) -> 0.010196037
A27: 42409 | B27: 11.92 | C27: 11.93 | D27: 11.96 | E27: 0 | F27: 0 | G27: =$M$2 + $M$3*C27 + $M$4*D27 + $M$5*E27 + $M$6*F27 -> 12.016193 | H27: =B27 - G27 -> -0.096193306 | I27: =ABS(H27) -> 0.096193306 | J27: =POWER(H27, 2) -> 0.0092531521
A28: 42410 | B28: 11.91 | C28: 11.92 | D28: 11.96 | E28: 0 | F28: 0 | G28: =$M$2 + $M$3*C28 + $M$4*D28 + $M$5*E28 + $M$6*F28 -> 12.010166 | H28: =B28 - G28 -> -0.10016644 | I28: =ABS(H28) -> 0.10016644 | J28: =POWER(H28, 2) -> 0.010033317
A29: 42411 | B29: 11.91 | C29: 11.91 | D29: 11.93 | E29: 0 | F29: 0 | G29: =$M$2 + $M$3*C29 + $M$4*D29 + $M$5*E29 + $M$6*F29 -> 12.001666 | H29: =B29 - G29 -> -0.091665736 | I29: =ABS(H29) -> 0.091665736 | J29: =POWER(H29, 2) -> 0.0084026072
... A1771: 44707 | B1771: 11.96 | C1771: 11.56 | D1771: 12.46 | E1771: 0 | F1771: 0 | G1771: =$M$2 + $M$3*C1771 + $M$4*D1771 + $M$5*E1771 + $M$6*F1771 -> 11.83443 | H1771: =B1771 - G1771 -> 0.12556976 | I1771: =ABS(H1771) -> 0.12556976 | J1771: =POWER(H1771, 2) -> 0.015767765

Sheet Val_Cand_01_Baseline_AR1
A1: Date | B1: Actual_Y | C1: Sto_Nino_DailyMaxWL_t_1 | D1: Pred_Y_Formula | E1: Residual_Formula | F1: Abs_Error_Formula | G1: Sq_Error_Formula | I1: PARAMETER | J1: TRAINED VALUE
A2: 44708 | B2: 11.93 | C2: 11.96 | D2: =$J$2 + $J$3*C2 -> 12.022266 | E2: =B2 - D2 -> -0.092265731 | F2: =ABS(E2) -> 0.092265731 | G2: =POWER(E2, 2) -> 0.0085129651 | I2: beta_0 (Intercept) | J2: 6.9994291
A3: 44709 | B3: 11.92 | C3: 11.93 | D3: =$J$2 + $J$3*C3 -> 12.009667 | E3: =B3 - D3 -> -0.089666642 | F3: =ABS(E3) -> 0.089666642 | G3: =POWER(E3, 2) -> 0.0080401067 | I3: beta_1 (Sto_Nino_DailyMaxWL_t_1) | J3: 0.41996962
A4: 44710 | B4: 11.91 | C4: 11.92 | D4: =$J$2 + $J$3*C4 -> 12.005467 | E4: =B4 - D4 -> -0.095466946 | F4: =ABS(E4) -> 0.095466946 | G4: =POWER(E4, 2) -> 0.0091139378
A5: 44711 | B5: 11.9 | C5: 11.91 | D5: =$J$2 + $J$3*C5 -> 12.001267 | E5: =B5 - D5 -> -0.10126725 | F5: =ABS(E5) -> 0.10126725 | G5: =POWER(E5, 2) -> 0.010255056 | I5: VALIDATION METRIC | J5: EXCEL FORMULA VALUE
A6: 44712 | B6: 12.37 | C6: 11.9 | D6: =$J$2 + $J$3*C6 -> 11.997068 | E6: =B6 - D6 -> 0.37293245 | F6: =ABS(E6) -> 0.37293245 | G6: =POWER(E6, 2) -> 0.13907861 | I6: Validation N | J6: =COUNT(B2:B511) -> 510
A7: 44713 | B7: 11.45 | C7: 12.37 | D7: =$J$2 + $J$3*C7 -> 12.194453 | E7: =B7 - D7 -> -0.74445328 | F7: =ABS(E7) -> 0.74445328 | G7: =POWER(E7, 2) -> 0.55421068 | I7: Validation MAE (m) | J7: =AVERAGE(F2:F511) -> 0.3394953
A8: 44714 | B8: 11.46 | C8: 11.45 | D8: =$J$2 + $J$3*C8 -> 11.808081 | E8: =B8 - D8 -> -0.34808122 | F8: =ABS(E8) -> 0.34808122 | G8: =POWER(E8, 2) -> 0.12116054 | I8: Validation RMSE (m) | J8: =SQRT(AVERAGE(G2:G511)) -> 0.68043237
A9: 44715 | B9: 11.43 | C9: 11.46 | D9: =$J$2 + $J$3*C9 -> 11.812281 | E9: =B9 - D9 -> -0.38228092 | F9: =ABS(E9) -> 0.38228092 | G9: =POWER(E9, 2) -> 0.1461387 | I9: Validation Bias (m) | J9: =AVERAGE(E2:E511) -> 0.2055085
A10: 44716 | B10: 11.44 | C10: 11.43 | D10: =$J$2 + $J$3*C10 -> 11.799682 | E10: =B10 - D10 -> -0.35968183 | F10: =ABS(E10) -> 0.35968183 | G10: =POWER(E10, 2) -> 0.12937102 | I10: Validation SSE | J10: =SUM(G2:G511) -> 236.12399
A11: 44717 | B11: 11.45 | C11: 11.44 | D11: =$J$2 + $J$3*C11 -> 11.803882 | E11: =B11 - D11 -> -0.35388153 | F11: =ABS(E11) -> 0.35388153 | G11: =POWER(E11, 2) -> 0.12523214 | I11: Validation SST | J11: =DEVSQ(B2:B511) -> 389.69467
A12: 44718 | B12: 11.41 | C12: 11.45 | D12: =$J$2 + $J$3*C12 -> 11.808081 | E12: =B12 - D12 -> -0.39808122 | F12: =ABS(E12) -> 0.39808122 | G12: =POWER(E12, 2) -> 0.15846866 | I12: Validation R2 | J12: =1 - (J10 / J11) -> 0.39407951
A13: 44719 | B13: 11.4 | C13: 11.41 | D13: =$J$2 + $J$3*C13 -> 11.791282 | E13: =B13 - D13 -> -0.39128244 | F13: =ABS(E13) -> 0.39128244 | G13: =POWER(E13, 2) -> 0.15310195
A14: 44720 | B14: 11.52 | C14: 11.4 | D14: =$J$2 + $J$3*C14 -> 11.787083 | E14: =B14 - D14 -> -0.26708274 | F14: =ABS(E14) -> 0.26708274 | G14: =POWER(E14, 2) -> 0.071333192
A15: 44721 | B15: 11.35 | C15: 11.52 | D15: =$J$2 + $J$3*C15 -> 11.837479 | E15: =B15 - D15 -> -0.4874791 | F15: =ABS(E15) -> 0.4874791 | G15: =POWER(E15, 2) -> 0.23763587
A16: 44722 | B16: 11.31 | C16: 11.35 | D16: =$J$2 + $J$3*C16 -> 11.766084 | E16: =B16 - D16 -> -0.45608426 | F16: =ABS(E16) -> 0.45608426 | G16: =POWER(E16, 2) -> 0.20801285
A17: 44723 | B17: 11.37 | C17: 11.31 | D17: =$J$2 + $J$3*C17 -> 11.749285 | E17: =B17 - D17 -> -0.37928548 | F17: =ABS(E17) -> 0.37928548 | G17: =POWER(E17, 2) -> 0.14385747
A18: 44724 | B18: 11.46 | C18: 11.37 | D18: =$J$2 + $J$3*C18 -> 11.774484 | E18: =B18 - D18 -> -0.31448365 | F18: =ABS(E18) -> 0.31448365 | G18: =POWER(E18, 2) -> 0.098899969
A19: 44725 | B19: 11.68 | C19: 11.46 | D19: =$J$2 + $J$3*C19 -> 11.812281 | E19: =B19 - D19 -> -0.13228092 | F19: =ABS(E19) -> 0.13228092 | G19: =POWER(E19, 2) -> 0.017498242
A20: 44726 | B20: 11.57 | C20: 11.68 | D20: =$J$2 + $J$3*C20 -> 11.904674 | E20: =B20 - D20 -> -0.33467424 | F20: =ABS(E20) -> 0.33467424 | G20: =POWER(E20, 2) -> 0.11200684
A21: 44727 | B21: 11.89 | C21: 11.57 | D21: =$J$2 + $J$3*C21 -> 11.858478 | E21: =B21 - D21 -> 0.031522421 | F21: =ABS(E21) -> 0.031522421 | G21: =POWER(E21, 2) -> 0.00099366305
A22: 44728 | B22: 11.61 | C22: 11.89 | D22: =$J$2 + $J$3*C22 -> 11.992868 | E22: =B22 - D22 -> -0.38286786 | F22: =ABS(E22) -> 0.38286786 | G22: =POWER(E22, 2) -> 0.1465878
A23: 44729 | B23: 11.52 | C23: 11.61 | D23: =$J$2 + $J$3*C23 -> 11.875276 | E23: =B23 - D23 -> -0.35527636 | F23: =ABS(E23) -> 0.35527636 | G23: =POWER(E23, 2) -> 0.12622129
A24: 44730 | B24: 11.51 | C24: 11.52 | D24: =$J$2 + $J$3*C24 -> 11.837479 | E24: =B24 - D24 -> -0.3274791 | F24: =ABS(E24) -> 0.3274791 | G24: =POWER(E24, 2) -> 0.10724256
... A511: 45290 | B511: 12.06 | C511: 12.06 | D511: =$J$2 + $J$3*C511 -> 12.064263 | E511: =B511 - D511 -> -0.0042626931 | F511: =ABS(E511) -> 0.0042626931 | G511: =POWER(E511, 2) -> 1.8170552e-05

Sheet Val_Cand_02_AR2
A1: Date | B1: Actual_Y | C1: Sto_Nino_DailyMaxWL_t_1 | D1: Sto_Nino_DailyMaxWL_t_3 | E1: Pred_Y_Formula | F1: Residual_Formula | G1: Abs_Error_Formula | H1: Sq_Error_Formula | J1: PARAMETER | K1: TRAINED VALUE
A2: 44708 | B2: 11.93 | C2: 11.96 | D2: 11.99 | E2: =$K$2 + $K$3*C2 + $K$4*D2 -> 12.004396 | F2: =B2 - E2 -> -0.074395512 | G2: =ABS(F2) -> 0.074395512 | H2: =POWER(F2, 2) -> 0.0055346923 | J2: beta_0 (Intercept) | K2: 5.1011091
A3: 44709 | B3: 11.92 | C3: 11.93 | D3: 11.56 | E3: =$K$2 + $K$3*C3 + $K$4*D3 -> 11.886417 | F3: =B3 - E3 -> 0.033582714 | G3: =ABS(F3) -> 0.033582714 | H3: =POWER(F3, 2) -> 0.0011277987 | J3: beta_1 (Sto_Nino_DailyMaxWL_t_1) | K3: 0.32486341
A4: 44710 | B4: 11.91 | C4: 11.92 | D4: 11.96 | E4: =$K$2 + $K$3*C4 + $K$4*D4 -> 11.98385 | F4: =B4 - E4 -> -0.073849883 | G4: =ABS(F4) -> 0.073849883 | H4: =POWER(F4, 2) -> 0.0054538053 | J4: beta_2 (Sto_Nino_DailyMaxWL_t_3) | K4: 0.25170308
A5: 44711 | B5: 11.9 | C5: 11.91 | D5: 11.93 | E5: =$K$2 + $K$3*C5 + $K$4*D5 -> 11.97305 | F5: =B5 - E5 -> -0.073050157 | G5: =ABS(F5) -> 0.073050157 | H5: =POWER(F5, 2) -> 0.0053363254
A6: 44712 | B6: 12.37 | C6: 11.9 | D6: 11.92 | E6: =$K$2 + $K$3*C6 + $K$4*D6 -> 11.967284 | F6: =B6 - E6 -> 0.40271551 | G6: =ABS(F6) -> 0.40271551 | H6: =POWER(F6, 2) -> 0.16217978 | J6: VALIDATION METRIC | K6: EXCEL FORMULA VALUE
A7: 44713 | B7: 11.45 | C7: 12.37 | D7: 11.91 | E7: =$K$2 + $K$3*C7 + $K$4*D7 -> 12.117453 | F7: =B7 - E7 -> -0.66745327 | G7: =ABS(F7) -> 0.66745327 | H7: =POWER(F7, 2) -> 0.44549386 | J7: Validation N | K7: =COUNT(B2:B482) -> 481
A8: 44714 | B8: 11.46 | C8: 11.45 | D8: 11.9 | E8: =$K$2 + $K$3*C8 + $K$4*D8 -> 11.816062 | F8: =B8 - E8 -> -0.35606189 | G8: =ABS(F8) -> 0.35606189 | H8: =POWER(F8, 2) -> 0.12678007 | J8: Validation MAE (m) | K8: =AVERAGE(G2:G482) -> 0.31995645
A9: 44715 | B9: 11.43 | C9: 11.46 | D9: 12.37 | E9: =$K$2 + $K$3*C9 + $K$4*D9 -> 11.937611 | F9: =B9 - E9 -> -0.50761098 | G9: =ABS(F9) -> 0.50761098 | H9: =POWER(F9, 2) -> 0.2576689 | J9: Validation RMSE (m) | K9: =SQRT(AVERAGE(H2:H482)) -> 0.66611718
A10: 44716 | B10: 11.44 | C10: 11.43 | D10: 11.45 | E10: =$K$2 + $K$3*C10 + $K$4*D10 -> 11.696298 | F10: =B10 - E10 -> -0.25629824 | G10: =ABS(F10) -> 0.25629824 | H10: =POWER(F10, 2) -> 0.065688788 | J10: Validation Bias (m) | K10: =AVERAGE(F2:F482) -> 0.16575515
A11: 44717 | B11: 11.45 | C11: 11.44 | D11: 11.46 | E11: =$K$2 + $K$3*C11 + $K$4*D11 -> 11.702064 | F11: =B11 - E11 -> -0.2520639 | G11: =ABS(F11) -> 0.2520639 | H11: =POWER(F11, 2) -> 0.063536212 | J11: Validation SSE | K11: =SUM(H2:H482) -> 213.42552
A12: 44718 | B12: 11.41 | C12: 11.45 | D12: 11.43 | E12: =$K$2 + $K$3*C12 + $K$4*D12 -> 11.697761 | F12: =B12 - E12 -> -0.28776145 | G12: =ABS(F12) -> 0.28776145 | H12: =POWER(F12, 2) -> 0.08280665 | J12: Validation SST | K12: =DEVSQ(B2:B482) -> 386.2553
A13: 44719 | B13: 11.4 | C13: 11.41 | D13: 11.44 | E13: =$K$2 + $K$3*C13 + $K$4*D13 -> 11.687284 | F13: =B13 - E13 -> -0.28728394 | G13: =ABS(F13) -> 0.28728394 | H13: =POWER(F13, 2) -> 0.082532062 | J13: Validation R2 | K13: =1 - (K11 / K12) -> 0.4474496
A14: 44720 | B14: 11.52 | C14: 11.4 | D14: 11.45 | E14: =$K$2 + $K$3*C14 + $K$4*D14 -> 11.686552 | F14: =B14 - E14 -> -0.16655234 | G14: =ABS(F14) -> 0.16655234 | H14: =POWER(F14, 2) -> 0.027739681
A15: 44721 | B15: 11.35 | C15: 11.52 | D15: 11.41 | E15: =$K$2 + $K$3*C15 + $K$4*D15 -> 11.715468 | F15: =B15 - E15 -> -0.36546782 | G15: =ABS(F15) -> 0.36546782 | H15: =POWER(F15, 2) -> 0.13356673
A16: 44722 | B16: 11.31 | C16: 11.35 | D16: 11.4 | E16: =$K$2 + $K$3*C16 + $K$4*D16 -> 11.657724 | F16: =B16 - E16 -> -0.34772401 | G16: =ABS(F16) -> 0.34772401 | H16: =POWER(F16, 2) -> 0.12091199
A17: 44723 | B17: 11.37 | C17: 11.31 | D17: 11.52 | E17: =$K$2 + $K$3*C17 + $K$4*D17 -> 11.674934 | F17: =B17 - E17 -> -0.30493385 | G17: =ABS(F17) -> 0.30493385 | H17: =POWER(F17, 2) -> 0.09298465
A18: 44724 | B18: 11.46 | C18: 11.37 | D18: 11.35 | E18: =$K$2 + $K$3*C18 + $K$4*D18 -> 11.651636 | F18: =B18 - E18 -> -0.19163613 | G18: =ABS(F18) -> 0.19163613 | H18: =POWER(F18, 2) -> 0.036724405
A19: 44725 | B19: 11.68 | C19: 11.46 | D19: 11.31 | E19: =$K$2 + $K$3*C19 + $K$4*D19 -> 11.670806 | F19: =B19 - E19 -> 0.0091942891 | G19: =ABS(F19) -> 0.0091942891 | H19: =POWER(F19, 2) -> 8.4534951e-05
A20: 44726 | B20: 11.57 | C20: 11.68 | D20: 11.37 | E20: =$K$2 + $K$3*C20 + $K$4*D20 -> 11.757378 | F20: =B20 - E20 -> -0.18737785 | G20: =ABS(F20) -> 0.18737785 | H20: =POWER(F20, 2) -> 0.035110458
A21: 44727 | B21: 11.89 | C21: 11.57 | D21: 11.46 | E21: =$K$2 + $K$3*C21 + $K$4*D21 -> 11.744296 | F21: =B21 - E21 -> 0.14570385 | G21: =ABS(F21) -> 0.14570385 | H21: =POWER(F21, 2) -> 0.021229612
A22: 44728 | B22: 11.61 | C22: 11.89 | D22: 11.68 | E22: =$K$2 + $K$3*C22 + $K$4*D22 -> 11.903627 | F22: =B22 - E22 -> -0.29362712 | G22: =ABS(F22) -> 0.29362712 | H22: =POWER(F22, 2) -> 0.086216885
A23: 44729 | B23: 11.52 | C23: 11.61 | D23: 11.57 | E23: =$K$2 + $K$3*C23 + $K$4*D23 -> 11.784978 | F23: =B23 - E23 -> -0.26497802 | G23: =ABS(F23) -> 0.26497802 | H23: =POWER(F23, 2) -> 0.070213353
A24: 44730 | B24: 11.51 | C24: 11.52 | D24: 11.89 | E24: =$K$2 + $K$3*C24 + $K$4*D24 -> 11.836285 | F24: =B24 - E24 -> -0.3262853 | G24: =ABS(F24) -> 0.3262853 | H24: =POWER(F24, 2) -> 0.1064621
A25: 44731 | B25: 12.54 | C25: 11.51 | D25: 11.61 | E25: =$K$2 + $K$3*C25 + $K$4*D25 -> 11.76256 | F25: =B25 - E25 -> 0.77744019 | G25: =ABS(F25) -> 0.77744019 | H25: =POWER(F25, 2) -> 0.60441326
... A482: 45290 | B482: 12.06 | C482: 12.06 | D482: 12.07 | E482: =$K$2 + $K$3*C482 + $K$4*D482 -> 12.057018 | F482: =B482 - E482 -> 0.0029818998 | G482: =ABS(F482) -> 0.0029818998 | H482: =POWER(F482, 2) -> 8.8917265e-06

Sheet Val_Cand_03_AR1_NangkaWL
A1: Date | B1: Actual_Y | C1: Sto_Nino_DailyMaxWL_t_1 | D1: Nangka_DailyMaxWL_t_3 | E1: Pred_Y_Formula | F1: Residual_Formula | G1: Abs_Error_Formula | H1: Sq_Error_Formula | J1: PARAMETER | K1: TRAINED VALUE
A2: 44708 | B2: 11.93 | C2: 11.96 | D2: 15.86 | E2: =$K$2 + $K$3*C2 + $K$4*D2 -> 12.205925 | F2: =B2 - E2 -> -0.27592529 | G2: =ABS(F2) -> 0.27592529 | H2: =POWER(F2, 2) -> 0.076134763 | J2: beta_0 (Intercept) | K2: 2.7533382
A3: 44709 | B3: 11.92 | C3: 11.93 | D3: 15.86 | E3: =$K$2 + $K$3*C3 + $K$4*D3 -> 12.199212 | F3: =B3 - E3 -> -0.27921246 | G3: =ABS(F3) -> 0.27921246 | H3: =POWER(F3, 2) -> 0.0779596 | J3: beta_1 (Sto_Nino_DailyMaxWL_t_1) | K3: 0.22376072
A4: 44710 | B4: 11.91 | C4: 11.92 | D4: 15.86 | E4: =$K$2 + $K$3*C4 + $K$4*D4 -> 12.196975 | F4: =B4 - E4 -> -0.28697486 | G4: =ABS(F4) -> 0.28697486 | H4: =POWER(F4, 2) -> 0.082354568 | J4: beta_2 (Nangka_DailyMaxWL_t_3) | K4: 0.42726411
A5: 44711 | B5: 11.9 | C5: 11.91 | D5: 15.869 | E5: =$K$2 + $K$3*C5 + $K$4*D5 -> 12.198583 | F5: =B5 - E5 -> -0.29858263 | G5: =ABS(F5) -> 0.29858263 | H5: =POWER(F5, 2) -> 0.089151585
A6: 44712 | B6: 12.37 | C6: 11.9 | D6: 15.86 | E6: =$K$2 + $K$3*C6 + $K$4*D6 -> 12.1925 | F6: =B6 - E6 -> 0.17750036 | G6: =ABS(F6) -> 0.17750036 | H6: =POWER(F6, 2) -> 0.031506377 | J6: VALIDATION METRIC | K6: EXCEL FORMULA VALUE
A7: 44713 | B7: 11.45 | C7: 12.37 | D7: 15.86 | E7: =$K$2 + $K$3*C7 + $K$4*D7 -> 12.297667 | F7: =B7 - E7 -> -0.84766718 | G7: =ABS(F7) -> 0.84766718 | H7: =POWER(F7, 2) -> 0.71853965 | J7: Validation N | K7: =COUNT(B2:B372) -> 371
A8: 44714 | B8: 11.46 | C8: 11.45 | D8: 15.86 | E8: =$K$2 + $K$3*C8 + $K$4*D8 -> 12.091807 | F8: =B8 - E8 -> -0.63180732 | G8: =ABS(F8) -> 0.63180732 | H8: =POWER(F8, 2) -> 0.39918049 | J8: Validation MAE (m) | K8: =AVERAGE(G2:G372) -> 0.39650093
A9: 44715 | B9: 11.43 | C9: 11.46 | D9: 15.89 | E9: =$K$2 + $K$3*C9 + $K$4*D9 -> 12.106863 | F9: =B9 - E9 -> -0.67686285 | G9: =ABS(F9) -> 0.67686285 | H9: =POWER(F9, 2) -> 0.45814331 | J9: Validation RMSE (m) | K9: =SQRT(AVERAGE(H2:H372)) -> 0.71360657
A10: 44717 | B10: 11.45 | C10: 11.44 | D10: 15.86 | E10: =$K$2 + $K$3*C10 + $K$4*D10 -> 12.08957 | F10: =B10 - E10 -> -0.63956971 | G10: =ABS(F10) -> 0.63956971 | H10: =POWER(F10, 2) -> 0.40904941 | J10: Validation Bias (m) | K10: =AVERAGE(F2:F372) -> 0.031855688
A11: 44718 | B11: 11.41 | C11: 11.45 | D11: 15.86 | E11: =$K$2 + $K$3*C11 + $K$4*D11 -> 12.091807 | F11: =B11 - E11 -> -0.68180732 | G11: =ABS(F11) -> 0.68180732 | H11: =POWER(F11, 2) -> 0.46486122 | J11: Validation SSE | K11: =SUM(H2:H372) -> 188.92594
A12: 44719 | B12: 11.4 | C12: 11.41 | D12: 15.86 | E12: =$K$2 + $K$3*C12 + $K$4*D12 -> 12.082857 | F12: =B12 - E12 -> -0.68285689 | G12: =ABS(F12) -> 0.68285689 | H12: =POWER(F12, 2) -> 0.46629353 | J12: Validation SST | K12: =DEVSQ(B2:B372) -> 272.80299
A13: 44722 | B13: 11.31 | C13: 11.35 | D13: 15.86 | E13: =$K$2 + $K$3*C13 + $K$4*D13 -> 12.069431 | F13: =B13 - E13 -> -0.75943124 | G13: =ABS(F13) -> 0.75943124 | H13: =POWER(F13, 2) -> 0.57673581 | J13: Validation R2 | K13: =1 - (K11 / K12) -> 0.30746383
A14: 44723 | B14: 11.37 | C14: 11.31 | D14: 15.86 | E14: =$K$2 + $K$3*C14 + $K$4*D14 -> 12.060481 | F14: =B14 - E14 -> -0.69048082 | G14: =ABS(F14) -> 0.69048082 | H14: =POWER(F14, 2) -> 0.47676376
A15: 44724 | B15: 11.46 | C15: 11.37 | D15: 15.86 | E15: =$K$2 + $K$3*C15 + $K$4*D15 -> 12.073906 | F15: =B15 - E15 -> -0.61390646 | G15: =ABS(F15) -> 0.61390646 | H15: =POWER(F15, 2) -> 0.37688114
A16: 44725 | B16: 11.68 | C16: 11.46 | D16: 15.86 | E16: =$K$2 + $K$3*C16 + $K$4*D16 -> 12.094045 | F16: =B16 - E16 -> -0.41404492 | G16: =ABS(F16) -> 0.41404492 | H16: =POWER(F16, 2) -> 0.1714332
A17: 44727 | B17: 11.89 | C17: 11.57 | D17: 15.86 | E17: =$K$2 + $K$3*C17 + $K$4*D17 -> 12.118659 | F17: =B17 - E17 -> -0.2286586 | G17: =ABS(F17) -> 0.2286586 | H17: =POWER(F17, 2) -> 0.052284757
A18: 44729 | B18: 11.52 | C18: 11.61 | D18: 15.86 | E18: =$K$2 + $K$3*C18 + $K$4*D18 -> 12.127609 | F18: =B18 - E18 -> -0.60760903 | G18: =ABS(F18) -> 0.60760903 | H18: =POWER(F18, 2) -> 0.36918874
A19: 44730 | B19: 11.51 | C19: 11.52 | D19: 16.19 | E19: =$K$2 + $K$3*C19 + $K$4*D19 -> 12.248468 | F19: =B19 - E19 -> -0.73846772 | G19: =ABS(F19) -> 0.73846772 | H19: =POWER(F19, 2) -> 0.54533458
A20: 44731 | B20: 12.54 | C20: 11.51 | D20: 15.86 | E20: =$K$2 + $K$3*C20 + $K$4*D20 -> 12.105233 | F20: =B20 - E20 -> 0.43476704 | G20: =ABS(F20) -> 0.43476704 | H20: =POWER(F20, 2) -> 0.18902238
A21: 44732 | B21: 11.68 | C21: 12.54 | D21: 15.87 | E21: =$K$2 + $K$3*C21 + $K$4*D21 -> 12.339979 | F21: =B21 - E21 -> -0.65997915 | G21: =ABS(F21) -> 0.65997915 | H21: =POWER(F21, 2) -> 0.43557247
A22: 44733 | B22: 11.43 | C22: 11.68 | D22: 15.86 | E22: =$K$2 + $K$3*C22 + $K$4*D22 -> 12.143272 | F22: =B22 - E22 -> -0.71327228 | G22: =ABS(F22) -> 0.71327228 | H22: =POWER(F22, 2) -> 0.50875735
A23: 44736 | B23: 11.43 | C23: 11.74 | D23: 15.87 | E23: =$K$2 + $K$3*C23 + $K$4*D23 -> 12.160971 | F23: =B23 - E23 -> -0.73097057 | G23: =ABS(F23) -> 0.73097057 | H23: =POWER(F23, 2) -> 0.53431797
A24: 44737 | B24: 11.4 | C24: 11.43 | D24: 16.33 | E24: =$K$2 + $K$3*C24 + $K$4*D24 -> 12.288146 | F24: =B24 - E24 -> -0.88814623 | G24: =ABS(F24) -> 0.88814623 | H24: =POWER(F24, 2) -> 0.78880373
A25: 44741 | B25: 13.34 | C25: 11.98 | D25: 15.87 | E25: =$K$2 + $K$3*C25 + $K$4*D25 -> 12.214673 | F25: =B25 - E25 -> 1.1253269 | G25: =ABS(F25) -> 1.1253269 | H25: =POWER(F25, 2) -> 1.2663605
... A372: 45290 | B372: 12.06 | C372: 12.06 | D372: 15.93 | E372: =$K$2 + $K$3*C372 + $K$4*D372 -> 12.25821 | F372: =B372 - E372 -> -0.19820985 | G372: =ABS(F372) -> 0.19820985 | H372: =POWER(F372, 2) -> 0.039287143

Sheet Val_Cand_04_AR1_Boso
A1: Date | B1: Actual_Y | C1: Sto_Nino_DailyMaxWL_t_1 | D1: Mt_BosoBoso_Rain_t_1 | E1: Pred_Y_Formula | F1: Residual_Formula | G1: Abs_Error_Formula | H1: Sq_Error_Formula | J1: PARAMETER | K1: TRAINED VALUE
A2: 44708 | B2: 11.93 | C2: 11.96 | D2: 0 | E2: =$K$2 + $K$3*C2 + $K$4*D2 -> 11.903315 | F2: =B2 - E2 -> 0.026684689 | G2: =ABS(F2) -> 0.026684689 | H2: =POWER(F2, 2) -> 0.00071207264 | J2: beta_0 (Intercept) | K2: 7.0795422
A3: 44709 | B3: 11.92 | C3: 11.93 | D3: 0 | E3: =$K$2 + $K$3*C3 + $K$4*D3 -> 11.891216 | F3: =B3 - E3 -> 0.028784455 | G3: =ABS(F3) -> 0.028784455 | H3: =POWER(F3, 2) -> 0.00082854483 | J3: beta_1 (Sto_Nino_DailyMaxWL_t_1) | K3: 0.40332551
A4: 44710 | B4: 11.91 | C4: 11.92 | D4: 3 | E4: =$K$2 + $K$3*C4 + $K$4*D4 -> 11.951671 | F4: =B4 - E4 -> -0.041670697 | G4: =ABS(F4) -> 0.041670697 | H4: =POWER(F4, 2) -> 0.001736447 | J4: beta_2 (Mt_BosoBoso_Rain_t_1) | K4: 0.021496136
A5: 44711 | B5: 11.9 | C5: 11.91 | D5: 1 | E5: =$K$2 + $K$3*C5 + $K$4*D5 -> 11.904645 | F5: =B5 - E5 -> -0.0046451707 | G5: =ABS(F5) -> 0.0046451707 | H5: =POWER(F5, 2) -> 2.1577611e-05
A6: 44712 | B6: 12.37 | C6: 11.9 | D6: 3 | E6: =$K$2 + $K$3*C6 + $K$4*D6 -> 11.943604 | F6: =B6 - E6 -> 0.42639581 | G6: =ABS(F6) -> 0.42639581 | H6: =POWER(F6, 2) -> 0.18181339 | J6: VALIDATION METRIC | K6: EXCEL FORMULA VALUE
A7: 44713 | B7: 11.45 | C7: 12.37 | D7: 3 | E7: =$K$2 + $K$3*C7 + $K$4*D7 -> 12.133167 | F7: =B7 - E7 -> -0.68316718 | G7: =ABS(F7) -> 0.68316718 | H7: =POWER(F7, 2) -> 0.46671739 | J7: Validation N | K7: =COUNT(B2:B510) -> 509
A8: 44714 | B8: 11.46 | C8: 11.45 | D8: 1 | E8: =$K$2 + $K$3*C8 + $K$4*D8 -> 11.719115 | F8: =B8 - E8 -> -0.25911543 | G8: =ABS(F8) -> 0.25911543 | H8: =POWER(F8, 2) -> 0.067140808 | J8: Validation MAE (m) | K8: =AVERAGE(G2:G510) -> 0.36505988
A9: 44715 | B9: 11.43 | C9: 11.46 | D9: 1 | E9: =$K$2 + $K$3*C9 + $K$4*D9 -> 11.723149 | F9: =B9 - E9 -> -0.29314869 | G9: =ABS(F9) -> 0.29314869 | H9: =POWER(F9, 2) -> 0.085936154 | J9: Validation RMSE (m) | K9: =SQRT(AVERAGE(H2:H510)) -> 0.64112089
A10: 44716 | B10: 11.44 | C10: 11.43 | D10: 0 | E10: =$K$2 + $K$3*C10 + $K$4*D10 -> 11.689553 | F10: =B10 - E10 -> -0.24955279 | G10: =ABS(F10) -> 0.24955279 | H10: =POWER(F10, 2) -> 0.062276594 | J10: Validation Bias (m) | K10: =AVERAGE(F2:F510) -> 0.16512597
A11: 44717 | B11: 11.45 | C11: 11.44 | D11: 0 | E11: =$K$2 + $K$3*C11 + $K$4*D11 -> 11.693586 | F11: =B11 - E11 -> -0.24358604 | G11: =ABS(F11) -> 0.24358604 | H11: =POWER(F11, 2) -> 0.05933416 | J11: Validation SSE | K11: =SUM(H2:H510) -> 209.21732
A12: 44718 | B12: 11.41 | C12: 11.45 | D12: 0 | E12: =$K$2 + $K$3*C12 + $K$4*D12 -> 11.697619 | F12: =B12 - E12 -> -0.2876193 | G12: =ABS(F12) -> 0.2876193 | H12: =POWER(F12, 2) -> 0.082724861 | J12: Validation SST | K12: =DEVSQ(B2:B510) -> 389.57411
A13: 44719 | B13: 11.4 | C13: 11.41 | D13: 1 | E13: =$K$2 + $K$3*C13 + $K$4*D13 -> 11.702982 | F13: =B13 - E13 -> -0.30298241 | G13: =ABS(F13) -> 0.30298241 | H13: =POWER(F13, 2) -> 0.091798343 | J13: Validation R2 | K13: =1 - (K11 / K12) -> 0.46295886
A14: 44720 | B14: 11.52 | C14: 11.4 | D14: 0 | E14: =$K$2 + $K$3*C14 + $K$4*D14 -> 11.677453 | F14: =B14 - E14 -> -0.15745302 | G14: =ABS(F14) -> 0.15745302 | H14: =POWER(F14, 2) -> 0.024791454
A15: 44721 | B15: 11.35 | C15: 11.52 | D15: 14 | E15: =$K$2 + $K$3*C15 + $K$4*D15 -> 12.026798 | F15: =B15 - E15 -> -0.67679798 | G15: =ABS(F15) -> 0.67679798 | H15: =POWER(F15, 2) -> 0.45805551
A16: 44722 | B16: 11.31 | C16: 11.35 | D16: 0 | E16: =$K$2 + $K$3*C16 + $K$4*D16 -> 11.657287 | F16: =B16 - E16 -> -0.34728675 | G16: =ABS(F16) -> 0.34728675 | H16: =POWER(F16, 2) -> 0.12060808
A17: 44723 | B17: 11.37 | C17: 11.31 | D17: 0 | E17: =$K$2 + $K$3*C17 + $K$4*D17 -> 11.641154 | F17: =B17 - E17 -> -0.27115373 | G17: =ABS(F17) -> 0.27115373 | H17: =POWER(F17, 2) -> 0.073524343
A18: 44724 | B18: 11.46 | C18: 11.37 | D18: 3 | E18: =$K$2 + $K$3*C18 + $K$4*D18 -> 11.729842 | F18: =B18 - E18 -> -0.26984166 | G18: =ABS(F18) -> 0.26984166 | H18: =POWER(F18, 2) -> 0.072814524
A19: 44725 | B19: 11.68 | C19: 11.46 | D19: 2 | E19: =$K$2 + $K$3*C19 + $K$4*D19 -> 11.744645 | F19: =B19 - E19 -> -0.064644825 | G19: =ABS(F19) -> 0.064644825 | H19: =POWER(F19, 2) -> 0.0041789534
A20: 44726 | B20: 11.57 | C20: 11.68 | D20: 31 | E20: =$K$2 + $K$3*C20 + $K$4*D20 -> 12.456764 | F20: =B20 - E20 -> -0.88676438 | G20: =ABS(F20) -> 0.88676438 | H20: =POWER(F20, 2) -> 0.78635106
A21: 44727 | B21: 11.89 | C21: 11.57 | D21: 6 | E21: =$K$2 + $K$3*C21 + $K$4*D21 -> 11.874995 | F21: =B21 - E21 -> 0.015004825 | G21: =ABS(F21) -> 0.015004825 | H21: =POWER(F21, 2) -> 0.00022514478
A22: 44728 | B22: 11.61 | C22: 11.89 | D22: 5 | E22: =$K$2 + $K$3*C22 + $K$4*D22 -> 11.982563 | F22: =B22 - E22 -> -0.3725632 | G22: =ABS(F22) -> 0.3725632 | H22: =POWER(F22, 2) -> 0.13880334
A23: 44729 | B23: 11.52 | C23: 11.61 | D23: 0 | E23: =$K$2 + $K$3*C23 + $K$4*D23 -> 11.762151 | F23: =B23 - E23 -> -0.24215138 | G23: =ABS(F23) -> 0.24215138 | H23: =POWER(F23, 2) -> 0.058637291
A24: 44730 | B24: 11.51 | C24: 11.52 | D24: 0 | E24: =$K$2 + $K$3*C24 + $K$4*D24 -> 11.725852 | F24: =B24 - E24 -> -0.21585208 | G24: =ABS(F24) -> 0.21585208 | H24: =POWER(F24, 2) -> 0.046592122
A25: 44731 | B25: 12.54 | C25: 11.51 | D25: 0 | E25: =$K$2 + $K$3*C25 + $K$4*D25 -> 11.721819 | F25: =B25 - E25 -> 0.81818117 | G25: =ABS(F25) -> 0.81818117 | H25: =POWER(F25, 2) -> 0.66942043
... A510: 45290 | B510: 12.06 | C510: 12.06 | D510: 0 | E510: =$K$2 + $K$3*C510 + $K$4*D510 -> 11.943648 | F510: =B510 - E510 -> 0.11635214 | G510: =ABS(F510) -> 0.11635214 | H510: =POWER(F510, 2) -> 0.01353782

Sheet Val_Cand_05_AR1_Campana
A1: Date | B1: Actual_Y | C1: Sto_Nino_DailyMaxWL_t_1 | D1: Mt_Campana_Rain_t_1 | E1: Pred_Y_Formula | F1: Residual_Formula | G1: Abs_Error_Formula | H1: Sq_Error_Formula | J1: PARAMETER | K1: TRAINED VALUE
A2: 44708 | B2: 11.93 | C2: 11.96 | D2: 1 | E2: =$K$2 + $K$3*C2 + $K$4*D2 -> 12.066655 | F2: =B2 - E2 -> -0.1366553 | G2: =ABS(F2) -> 0.1366553 | H2: =POWER(F2, 2) -> 0.018674672 | J2: beta_0 (Intercept) | K2: 4.1081506
A3: 44709 | B3: 11.92 | C3: 11.93 | D3: 0 | E3: =$K$2 + $K$3*C3 + $K$4*D3 -> 12.038064 | F3: =B3 - E3 -> -0.11806391 | G3: =ABS(F3) -> 0.11806391 | H3: =POWER(F3, 2) -> 0.013939088 | J3: beta_1 (Sto_Nino_DailyMaxWL_t_1) | K3: 0.66470355
A4: 44710 | B4: 11.91 | C4: 11.92 | D4: 10 | E4: =$K$2 + $K$3*C4 + $K$4*D4 -> 12.11792 | F4: =B4 - E4 -> -0.2079197 | G4: =ABS(F4) -> 0.2079197 | H4: =POWER(F4, 2) -> 0.0432306 | J4: beta_2 (Mt_Campana_Rain_t_1) | K4: 0.0086502818
A5: 44711 | B5: 11.9 | C5: 11.91 | D5: 2 | E5: =$K$2 + $K$3*C5 + $K$4*D5 -> 12.04207 | F5: =B5 - E5 -> -0.14207041 | G5: =ABS(F5) -> 0.14207041 | H5: =POWER(F5, 2) -> 0.020184001
A6: 44712 | B6: 12.37 | C6: 11.9 | D6: 0 | E6: =$K$2 + $K$3*C6 + $K$4*D6 -> 12.018123 | F6: =B6 - E6 -> 0.35187719 | G6: =ABS(F6) -> 0.35187719 | H6: =POWER(F6, 2) -> 0.12381756 | J6: VALIDATION METRIC | K6: EXCEL FORMULA VALUE
A7: 44713 | B7: 11.45 | C7: 12.37 | D7: 3 | E7: =$K$2 + $K$3*C7 + $K$4*D7 -> 12.356484 | F7: =B7 - E7 -> -0.90648432 | G7: =ABS(F7) -> 0.90648432 | H7: =POWER(F7, 2) -> 0.82171382 | J7: Validation N | K7: =COUNT(B2:B509) -> 508
A8: 44714 | B8: 11.46 | C8: 11.45 | D8: 1 | E8: =$K$2 + $K$3*C8 + $K$4*D8 -> 11.727656 | F8: =B8 - E8 -> -0.26765649 | G8: =ABS(F8) -> 0.26765649 | H8: =POWER(F8, 2) -> 0.071639999 | J8: Validation MAE (m) | K8: =AVERAGE(G2:G509) -> 0.30700805
A9: 44715 | B9: 11.43 | C9: 11.46 | D9: 0 | E9: =$K$2 + $K$3*C9 + $K$4*D9 -> 11.725653 | F9: =B9 - E9 -> -0.29565325 | G9: =ABS(F9) -> 0.29565325 | H9: =POWER(F9, 2) -> 0.087410843 | J9: Validation RMSE (m) | K9: =SQRT(AVERAGE(H2:H509)) -> 0.5767804
A10: 44716 | B10: 11.44 | C10: 11.43 | D10: 0 | E10: =$K$2 + $K$3*C10 + $K$4*D10 -> 11.705712 | F10: =B10 - E10 -> -0.26571214 | G10: =ABS(F10) -> 0.26571214 | H10: =POWER(F10, 2) -> 0.070602942 | J10: Validation Bias (m) | K10: =AVERAGE(F2:F509) -> -0.010004022
A11: 44717 | B11: 11.45 | C11: 11.44 | D11: 6 | E11: =$K$2 + $K$3*C11 + $K$4*D11 -> 11.764261 | F11: =B11 - E11 -> -0.31426087 | G11: =ABS(F11) -> 0.31426087 | H11: =POWER(F11, 2) -> 0.098759893 | J11: Validation SSE | K11: =SUM(H2:H509) -> 168.99922
A12: 44718 | B12: 11.41 | C12: 11.45 | D12: 1 | E12: =$K$2 + $K$3*C12 + $K$4*D12 -> 11.727656 | F12: =B12 - E12 -> -0.31765649 | G12: =ABS(F12) -> 0.31765649 | H12: =POWER(F12, 2) -> 0.10090565 | J12: Validation SST | K12: =DEVSQ(B2:B509) -> 389.32606
A13: 44719 | B13: 11.4 | C13: 11.41 | D13: 32 | E13: =$K$2 + $K$3*C13 + $K$4*D13 -> 11.969227 | F13: =B13 - E13 -> -0.56922709 | G13: =ABS(F13) -> 0.56922709 | H13: =POWER(F13, 2) -> 0.32401948 | J13: Validation R2 | K13: =1 - (K11 / K12) -> 0.56591856
A14: 44720 | B14: 11.52 | C14: 11.4 | D14: 0 | E14: =$K$2 + $K$3*C14 + $K$4*D14 -> 11.685771 | F14: =B14 - E14 -> -0.16577104 | G14: =ABS(F14) -> 0.16577104 | H14: =POWER(F14, 2) -> 0.027480036
A15: 44721 | B15: 11.35 | C15: 11.52 | D15: 9 | E15: =$K$2 + $K$3*C15 + $K$4*D15 -> 11.843388 | F15: =B15 - E15 -> -0.493388 | G15: =ABS(F15) -> 0.493388 | H15: =POWER(F15, 2) -> 0.24343172
A16: 44722 | B16: 11.31 | C16: 11.35 | D16: 0 | E16: =$K$2 + $K$3*C16 + $K$4*D16 -> 11.652536 | F16: =B16 - E16 -> -0.34253586 | G16: =ABS(F16) -> 0.34253586 | H16: =POWER(F16, 2) -> 0.11733081
A17: 44723 | B17: 11.37 | C17: 11.31 | D17: 0 | E17: =$K$2 + $K$3*C17 + $K$4*D17 -> 11.625948 | F17: =B17 - E17 -> -0.25594772 | G17: =ABS(F17) -> 0.25594772 | H17: =POWER(F17, 2) -> 0.065509233
A18: 44724 | B18: 11.46 | C18: 11.37 | D18: 0 | E18: =$K$2 + $K$3*C18 + $K$4*D18 -> 11.66583 | F18: =B18 - E18 -> -0.20582993 | G18: =ABS(F18) -> 0.20582993 | H18: =POWER(F18, 2) -> 0.04236596
A19: 44725 | B19: 11.68 | C19: 11.46 | D19: 0 | E19: =$K$2 + $K$3*C19 + $K$4*D19 -> 11.725653 | F19: =B19 - E19 -> -0.045653248 | G19: =ABS(F19) -> 0.045653248 | H19: =POWER(F19, 2) -> 0.002084219
A20: 44726 | B20: 11.57 | C20: 11.68 | D20: 38 | E20: =$K$2 + $K$3*C20 + $K$4*D20 -> 12.200599 | F20: =B20 - E20 -> -0.63059874 | G20: =ABS(F20) -> 0.63059874 | H20: =POWER(F20, 2) -> 0.39765477
A21: 44727 | B21: 11.89 | C21: 11.57 | D21: 0 | E21: =$K$2 + $K$3*C21 + $K$4*D21 -> 11.798771 | F21: =B21 - E21 -> 0.091229362 | G21: =ABS(F21) -> 0.091229362 | H21: =POWER(F21, 2) -> 0.0083227965
A22: 44728 | B22: 11.61 | C22: 11.89 | D22: 1 | E22: =$K$2 + $K$3*C22 + $K$4*D22 -> 12.020126 | F22: =B22 - E22 -> -0.41012605 | G22: =ABS(F22) -> 0.41012605 | H22: =POWER(F22, 2) -> 0.16820338
A23: 44729 | B23: 11.52 | C23: 11.61 | D23: 29 | E23: =$K$2 + $K$3*C23 + $K$4*D23 -> 12.076217 | F23: =B23 - E23 -> -0.55621695 | G23: =ABS(F23) -> 0.55621695 | H23: =POWER(F23, 2) -> 0.3093773
A24: 44730 | B24: 11.51 | C24: 11.52 | D24: 0 | E24: =$K$2 + $K$3*C24 + $K$4*D24 -> 11.765535 | F24: =B24 - E24 -> -0.25553546 | G24: =ABS(F24) -> 0.25553546 | H24: =POWER(F24, 2) -> 0.065298372
A25: 44731 | B25: 12.54 | C25: 11.51 | D25: 6 | E25: =$K$2 + $K$3*C25 + $K$4*D25 -> 11.81079 | F25: =B25 - E25 -> 0.72920988 | G25: =ABS(F25) -> 0.72920988 | H25: =POWER(F25, 2) -> 0.53174706
... A509: 45290 | B509: 12.06 | C509: 12.06 | D509: 0 | E509: =$K$2 + $K$3*C509 + $K$4*D509 -> 12.124475 | F509: =B509 - E509 -> -0.064475376 | G509: =ABS(F509) -> 0.064475376 | H509: =POWER(F509, 2) -> 0.0041570741

Sheet Val_Cand_06_AR1_NangkaRain
A1: Date | B1: Actual_Y | C1: Sto_Nino_DailyMaxWL_t_1 | D1: Nangka_Rain_t_1 | E1: Pred_Y_Formula | F1: Residual_Formula | G1: Abs_Error_Formula | H1: Sq_Error_Formula | J1: PARAMETER | K1: TRAINED VALUE
A2: 44708 | B2: 11.93 | C2: 11.96 | D2: 17 | E2: =$K$2 + $K$3*C2 + $K$4*D2 -> 12.182761 | F2: =B2 - E2 -> -0.25276097 | G2: =ABS(F2) -> 0.25276097 | H2: =POWER(F2, 2) -> 0.063888109 | J2: beta_0 (Intercept) | K2: 7.0839747
A3: 44709 | B3: 11.92 | C3: 11.93 | D3: 0 | E3: =$K$2 + $K$3*C3 + $K$4*D3 -> 11.837736 | F3: =B3 - E3 -> 0.082264361 | G3: =ABS(F3) -> 0.082264361 | H3: =POWER(F3, 2) -> 0.0067674251 | J3: beta_1 (Sto_Nino_DailyMaxWL_t_1) | K3: 0.39847116
A4: 44710 | B4: 11.91 | C4: 11.92 | D4: 2 | E4: =$K$2 + $K$3*C4 + $K$4*D4 -> 11.872936 | F4: =B4 - E4 -> 0.037064225 | G4: =ABS(F4) -> 0.037064225 | H4: =POWER(F4, 2) -> 0.0013737568 | J4: beta_2 (Nangka_Rain_t_1) | K4: 0.019592423
A5: 44711 | B5: 11.9 | C5: 11.91 | D5: 0 | E5: =$K$2 + $K$3*C5 + $K$4*D5 -> 11.829766 | F5: =B5 - E5 -> 0.070233784 | G5: =ABS(F5) -> 0.070233784 | H5: =POWER(F5, 2) -> 0.0049327844
A6: 44712 | B6: 12.37 | C6: 11.9 | D6: 0 | E6: =$K$2 + $K$3*C6 + $K$4*D6 -> 11.825782 | F6: =B6 - E6 -> 0.5442185 | G6: =ABS(F6) -> 0.5442185 | H6: =POWER(F6, 2) -> 0.29617377 | J6: VALIDATION METRIC | K6: EXCEL FORMULA VALUE
A7: 44713 | B7: 11.45 | C7: 12.37 | D7: 5 | E7: =$K$2 + $K$3*C7 + $K$4*D7 -> 12.111025 | F7: =B7 - E7 -> -0.66102507 | G7: =ABS(F7) -> 0.66102507 | H7: =POWER(F7, 2) -> 0.43695414 | J7: Validation N | K7: =COUNT(B2:B473) -> 472
